Workbook

Sheet Historical
A1: NAME | B1: SIZE | C1: ISODATE | D1: RCP
A2: ACCESS-CM2.r1i1p1f1 | B2: 16.9 | C2: 2025-07-23T21:19:26.082Z | D2: 0
A3: ACCESS-CM2.r2i1p1f1 | B3: 15.09 | C3: 2023-08-02T08:21:04.615Z | D3: 0
A4: ACCESS-CM2.r3i1p1f1 | B4: 15.31 | C4: 2023-06-09T04:10:18.992Z | D4: 0
A5: ACCESS-ESM1-5.r1i1p1f1 | B5: 16.92 | C5: 2025-07-22T22:14:55.100Z | D5: 0
A6: ACCESS-ESM1-5.r2i1p1f1 | B6: 15.1 | C6: 2023-08-03T07:18:12.303Z | D6: 0
A7: ACCESS-ESM1-5.r5i1p1f1 | B7: 15.31 | C7: 2023-06-08T18:41:48.449Z | D7: 0
A8: AWI-CM-1-1-MR.r1i1p1f1 | B8: 16.91 | C8: 2025-07-26T03:04:58.472Z | D8: 0
A9: AWI-CM-1-1-MR.r2i1p1f1 | B9: 15.29 | C9: 2023-06-15T03:40:01.950Z | D9: 0
A10: AWI-CM-1-1-MR.r4i1p1f1 | B10: 15.11 | C10: 2023-08-17T11:58:02.316Z | D10: 0
A11: BCC-CSM2-MR.r1i1p1f1 | B11: 16.94 | C11: 2025-07-16T19:20:21.670Z | D11: 0
A12: CESM2-LENS.r1i1p1f1 | B12: 15.21 | C12: 2023-06-27T08:55:37.559Z | D12: 0
A13: CESM2-LENS.r4i1p1f1 | B13: 16.84 | C13: 2025-07-24T01:47:07.387Z | D13: 0
... A70: TaiESM1.r1i1p1f1 | B70: 16.88 | C70: 2025-07-19T01:33:03.035Z | D70: 0

Sheet SSP2-4.5
A1: NAME | B1: SIZE | C1: ISODATE | D1: RCP
A2: ACCESS-CM2.r1i1p1f1 | B2: 22.45 | C2: 2025-07-24T03:08:55.616Z | D2: 4
A3: ACCESS-CM2.r2i1p1f1 | B3: 20.07 | C3: 2023-08-04T02:25:48.378Z | D3: 4
A4: ACCESS-CM2.r3i1p1f1 | B4: 20.36 | C4: 2023-06-09T06:55:33.364Z | D4: 4
A5: ACCESS-ESM1-5.r1i1p1f1 | B5: 22.44 | C5: 2025-07-23T04:03:17.082Z | D5: 4
A6: ACCESS-ESM1-5.r2i1p1f1 | B6: 20.02 | C6: 2023-08-04T03:13:24.785Z | D6: 4
A7: ACCESS-ESM1-5.r5i1p1f1 | B7: 20.31 | C7: 2023-06-08T23:49:50.942Z | D7: 4
A8: AWI-CM-1-1-MR.r1i1p1f1 | B8: 22.29 | C8: 2025-07-26T08:54:10.031Z | D8: 4
A9: BCC-CSM2-MR.r1i1p1f1 | B9: 22.51 | C9: 2025-07-17T01:38:59.708Z | D9: 4
A10: CNRM-CM6-1.r1i1p1f2 | B10: 22.37 | C10: 2025-07-18T04:50:11.940Z | D10: 4
A11: CNRM-ESM2-1.r1i1p1f2 | B11: 22.34 | C11: 2025-07-19T06:56:16.993Z | D11: 4
A12: CanESM5.r1i1p1f1 | B12: 22.55 | C12: 2025-07-24T03:21:50.035Z | D12: 4
A13: CanESM5.r4i1p1f1 | B13: 20.44 | C13: 2023-06-16T11:38:17.514Z | D13: 4
... A50: TaiESM1.r1i1p1f1 | B50: 22.44 | C50: 2025-07-19T07:09:44.844Z | D50: 4

Sheet SSP3-7.0
A1: NAME | B1: SIZE | C1: ISODATE | D1: RCP
A2: ACCESS-CM2.r1i1p1f1 | B2: 22.47 | C2: 2025-07-24T08:58:57.515Z | D2: 7
A3: ACCESS-CM2.r2i1p1f1 | B3: 20.06 | C3: 2023-08-03T09:40:36.602Z | D3: 7
A4: ACCESS-CM2.r3i1p1f1 | B4: 20.38 | C4: 2023-06-09T06:52:31.430Z | D4: 7
A5: ACCESS-ESM1-5.r1i1p1f1 | B5: 22.42 | C5: 2025-07-23T09:52:27.697Z | D5: 7
A6: ACCESS-ESM1-5.r2i1p1f1 | B6: 20.03 | C6: 2023-08-03T09:59:44.229Z | D6: 7
A7: ACCESS-ESM1-5.r5i1p1f1 | B7: 20.29 | C7: 2023-06-08T23:53:39.172Z | D7: 7
A8: AWI-CM-1-1-MR.r1i1p1f1 | B8: 22.24 | C8: 2025-07-26T14:37:23.877Z | D8: 7
A9: AWI-CM-1-1-MR.r2i1p1f1 | B9: 20.16 | C9: 2023-06-15T07:12:50.787Z | D9: 7
A10: AWI-CM-1-1-MR.r4i1p1f1 | B10: 19.83 | C10: 2023-08-17T14:02:00.058Z | D10: 7
A11: BCC-CSM2-MR.r1i1p1f1 | B11: 22.48 | C11: 2025-07-17T07:05:51.138Z | D11: 7
A12: CESM2-LENS.r1i1p1f1 | B12: 20.25 | C12: 2023-06-23T05:48:08.253Z | D12: 7
A13: CESM2-LENS.r4i1p1f1 | B13: 22.39 | C13: 2025-07-24T13:14:17.214Z | D13: 7
... A57: TaiESM1.r1i1p1f1 | B57: 22.43 | C57: 2025-07-19T12:45:28.809Z | D57: 7

Sheet SSP5-8.5
A1: NAMES | B1: SIZE | C1: ISODATE | D1: RCP
A2: ACCESS-CM2.r1i1p1f1 | B2: 22.47 | C2: 2025-07-24T14:45:43.813Z | D2: 8
A3: ACCESS-CM2.r2i1p1f1 | B3: 20.13 | C3: 2023-08-03T09:43:39.731Z | D3: 8
A4: ACCESS-CM2.r3i1p1f1 | B4: 20.37 | C4: 2023-06-09T06:52:42.210Z | D4: 8
A5: ACCESS-ESM1-5.r1i1p1f1 | B5: 22.43 | C5: 2025-07-23T15:36:32.651Z | D5: 8
A6: ACCESS-ESM1-5.r2i1p1f1 | B6: 20.02 | C6: 2023-08-02T11:36:28.103Z | D6: 8
A7: ACCESS-ESM1-5.r5i1p1f1 | B7: 20.29 | C7: 2023-06-08T23:44:02.130Z | D7: 8
A8: AWI-CM-1-1-MR.r1i1p1f1 | B8: 22.25 | C8: 2025-07-26T20:32:51.486Z | D8: 8
A9: BCC-CSM2-MR.r1i1p1f1 | B9: 22.49 | C9: 2025-07-17T12:41:28.612Z | D9: 8
A10: CNRM-CM6-1-HR.r1i1p1f2 | B10: 22.42 | C10: 2025-07-20T02:59:24.113Z | D10: 8
A11: CNRM-CM6-1.r1i1p1f2 | B11: 22.35 | C11: 2025-07-18T17:37:30.973Z | D11: 8
A12: CNRM-ESM2-1.r1i1p1f2 | B12: 22.32 | C12: 2025-07-19T17:59:57.033Z | D12: 8
A13: CanESM5.r1i1p1f1 | B13: 22.5 | C13: 2025-07-24T15:05:04.124Z | D13: 8
... A50: NorESM2-MM.r1i1p1f1 | B50: 20.28 | C50: 2023-06-10T20:54:13.370Z | D50: 8

Sheet available_inv
A1: Model_Member | B1: Model | C1: Member | D1: Var | E1: Season | F1: Stat | G1: NetError | H1: Rank | I1: historical | J1: ssp245 | K1: ssp370 | L1: ssp585 | M1: Mmem | N1: Have H | O1: Have 4 | P1: Have 7 | Q1: Have 8
A2: 1 | B2: GFDL-ESM4 | C2: r1i1p1f1 | D2: All | E2: Annual | F2: Both | G2: 6.1522354 | H2: 1 | I2: 0 | J2: 4 | K2: 7 | L2: 8 | M2: GFDL-ESM4.r1i1p1f1 | N2: =IF(ISNA(I2),"--",_xlfn.XLOOKUP($M2,Historical!$A$2:$A$70,Historical!$C$2:$C$70,"ERROR")) -> 2025-07-14T05:20:35.850Z | O2: =IF(ISNA(J2),"--",_xlfn.XLOOKUP($M2,'SSP2-4.5'!$A$2:$A$70,'SSP2-4.5'!$C$2:$C$70,"ERROR")) -> 2025-07-12T01:34:39.139Z | P2: =IF(ISNA(K2),"--",_xlfn.XLOOKUP($M2,'SSP3-7.0'!$A$2:$A$70,'SSP3-7.0'!$C$2:$C$70,"ERROR")) -> 2025-07-14T11:17:30.368Z | Q2: =IF(ISNA(L2),"--",_xlfn.XLOOKUP($M2,'SSP5-8.5'!$A$2:$A$70,'SSP5-8.5'!$C$2:$C$70,"ERROR")) -> 2025-07-14T18:47:12.147Z
A3: 2 | B3: BCC-CSM2-MR | C3: r1i1p1f1 | D3: All | E3: Annual | F3: Both | G3: 6.3576725 | H3: 1 | I3: 0 | J3: 4 | K3: 7 | L3: 8 | M3: BCC-CSM2-MR.r1i1p1f1 | N3: =IF(ISNA(I3),"--",_xlfn.XLOOKUP($M3,Historical!$A$2:$A$70,Historical!$C$2:$C$70,"ERROR")) -> 2025-07-16T19:20:21.670Z | O3: =IF(ISNA(J3),"--",_xlfn.XLOOKUP($M3,'SSP2-4.5'!$A$2:$A$70,'SSP2-4.5'!$C$2:$C$70,"ERROR")) -> 2025-07-17T01:38:59.708Z | P3: =IF(ISNA(K3),"--",_xlfn.XLOOKUP($M3,'SSP3-7.0'!$A$2:$A$70,'SSP3-7.0'!$C$2:$C$70,"ERROR")) -> 2025-07-17T07:05:51.138Z | Q3: =IF(ISNA(L3),"--",_xlfn.XLOOKUP($M3,'SSP5-8.5'!$A$2:$A$70,'SSP5-8.5'!$C$2:$C$70,"ERROR")) -> 2025-07-17T12:41:28.612Z
A4: 3 | B4: GFDL-CM4 | C4: r1i1p1f1 | D4: All | E4: Annual | F4: Both | G4: 6.4984614 | H4: 1 | I4: 0 | J4: 4 | K4: =NA() -> #N/A | L4: 8 | M4: GFDL-CM4.r1i1p1f1 | N4: =IF(ISNA(I4),"--",_xlfn.XLOOKUP($M4,Historical!$A$2:$A$70,Historical!$C$2:$C$70,"ERROR")) -> 2025-07-15T01:33:03.787Z | O4: =IF(ISNA(J4),"--",_xlfn.XLOOKUP($M4,'SSP2-4.5'!$A$2:$A$70,'SSP2-4.5'!$C$2:$C$70,"ERROR")) -> 2025-07-15T07:38:40.287Z | P4: =IF(ISNA(K4),"--",_xlfn.XLOOKUP($M4,'SSP3-7.0'!$A$2:$A$70,'SSP3-7.0'!$C$2:$C$70,"ERROR")) -> -- | Q4: =IF(ISNA(L4),"--",_xlfn.XLOOKUP($M4,'SSP5-8.5'!$A$2:$A$70,'SSP5-8.5'!$C$2:$C$70,"ERROR")) -> 2025-07-15T13:17:48.656Z
A5: 4 | B5: CNRM-CM6-1 | C5: r1i1p1f2 | D5: All | E5: Annual | F5: Both | G5: 6.5130638 | H5: 1 | I5: 0 | J5: 4 | K5: 7 | L5: 8 | M5: CNRM-CM6-1.r1i1p1f2 | N5: =IF(ISNA(I5),"--",_xlfn.XLOOKUP($M5,Historical!$A$2:$A$70,Historical!$C$2:$C$70,"ERROR")) -> 2025-07-17T23:02:44.532Z | O5: =IF(ISNA(J5),"--",_xlfn.XLOOKUP($M5,'SSP2-4.5'!$A$2:$A$70,'SSP2-4.5'!$C$2:$C$70,"ERROR")) -> 2025-07-18T04:50:11.940Z | P5: =IF(ISNA(K5),"--",_xlfn.XLOOKUP($M5,'SSP3-7.0'!$A$2:$A$70,'SSP3-7.0'!$C$2:$C$70,"ERROR")) -> 2025-07-18T11:58:08.339Z | Q5: =IF(ISNA(L5),"--",_xlfn.XLOOKUP($M5,'SSP5-8.5'!$A$2:$A$70,'SSP5-8.5'!$C$2:$C$70,"ERROR")) -> 2025-07-18T17:37:30.973Z
A6: 5 | B6: TaiESM1 | C6: r1i1p1f1 | D6: All | E6: Annual | F6: Both | G6: 6.6588287 | H6: 1 | I6: 0 | J6: 4 | K6: 7 | L6: =NA() -> #N/A | M6: TaiESM1.r1i1p1f1 | N6: =IF(ISNA(I6),"--",_xlfn.XLOOKUP($M6,Historical!$A$2:$A$70,Historical!$C$2:$C$70,"ERROR")) -> 2025-07-19T01:33:03.035Z | O6: =IF(ISNA(J6),"--",_xlfn.XLOOKUP($M6,'SSP2-4.5'!$A$2:$A$70,'SSP2-4.5'!$C$2:$C$70,"ERROR")) -> 2025-07-19T07:09:44.844Z | P6: =IF(ISNA(K6),"--",_xlfn.XLOOKUP($M6,'SSP3-7.0'!$A$2:$A$70,'SSP3-7.0'!$C$2:$C$70,"ERROR")) -> 2025-07-19T12:45:28.809Z | Q6: =IF(ISNA(L6),"--",_xlfn.XLOOKUP($M6,'SSP5-8.5'!$A$2:$A$70,'SSP5-8.5'!$C$2:$C$70,"ERROR")) -> --
A7: 6 | B7: CNRM-ESM2-1 | C7: r1i1p1f2 | D7: All | E7: Annual | F7: Both | G7: 6.6813172 | H7: 1 | I7: 0 | J7: 4 | K7: 7 | L7: 8 | M7: CNRM-ESM2-1.r1i1p1f2 | N7: =IF(ISNA(I7),"--",_xlfn.XLOOKUP($M7,Historical!$A$2:$A$70,Historical!$C$2:$C$70,"ERROR")) -> 2025-07-19T01:22:36.215Z | O7: =IF(ISNA(J7),"--",_xlfn.XLOOKUP($M7,'SSP2-4.5'!$A$2:$A$70,'SSP2-4.5'!$C$2:$C$70,"ERROR")) -> 2025-07-19T06:56:16.993Z | P7: =IF(ISNA(K7),"--",_xlfn.XLOOKUP($M7,'SSP3-7.0'!$A$2:$A$70,'SSP3-7.0'!$C$2:$C$70,"ERROR")) -> 2025-07-19T12:28:19.480Z | Q7: =IF(ISNA(L7),"--",_xlfn.XLOOKUP($M7,'SSP5-8.5'!$A$2:$A$70,'SSP5-8.5'!$C$2:$C$70,"ERROR")) -> 2025-07-19T17:59:57.033Z
A8: 7 | B8: CNRM-CM6-1-HR | C8: r1i1p1f2 | D8: All | E8: Annual | F8: Both | G8: 6.9907081 | H8: 1 | I8: 0 | J8: =NA() -> #N/A | K8: =NA() -> #N/A | L8: 8 | M8: CNRM-CM6-1-HR.r1i1p1f2 | N8: =IF(ISNA(I8),"--",_xlfn.XLOOKUP($M8,Historical!$A$2:$A$70,Historical!$C$2:$C$70,"ERROR")) -> 2025-07-19T21:28:43.171Z | O8: =IF(ISNA(J8),"--",_xlfn.XLOOKUP($M8,'SSP2-4.5'!$A$2:$A$70,'SSP2-4.5'!$C$2:$C$70,"ERROR")) -> -- | P8: =IF(ISNA(K8),"--",_xlfn.XLOOKUP($M8,'SSP3-7.0'!$A$2:$A$70,'SSP3-7.0'!$C$2:$C$70,"ERROR")) -> -- | Q8: =IF(ISNA(L8),"--",_xlfn.XLOOKUP($M8,'SSP5-8.5'!$A$2:$A$70,'SSP5-8.5'!$C$2:$C$70,"ERROR")) -> 2025-07-20T02:59:24.113Z
A9: 8 | B9: INM-CM4-8 | C9: r1i1p1f1 | D9: All | E9: Annual | F9: Both | G9: 7.2380937 | H9: 1 | I9: 0 | J9: 4 | K9: 7 | L9: 8 | M9: INM-CM4-8.r1i1p1f1 | N9: =IF(ISNA(I9),"--",_xlfn.XLOOKUP($M9,Historical!$A$2:$A$70,Historical!$C$2:$C$70,"ERROR")) -> 2025-07-19T21:32:52.304Z | O9: =IF(ISNA(J9),"--",_xlfn.XLOOKUP($M9,'SSP2-4.5'!$A$2:$A$70,'SSP2-4.5'!$C$2:$C$70,"ERROR")) -> 2025-07-20T03:05:59.447Z | P9: =IF(ISNA(K9),"--",_xlfn.XLOOKUP($M9,'SSP3-7.0'!$A$2:$A$70,'SSP3-7.0'!$C$2:$C$70,"ERROR")) -> 2025-07-20T08:34:26.619Z | Q9: =IF(ISNA(L9),"--",_xlfn.XLOOKUP($M9,'SSP5-8.5'!$A$2:$A$70,'SSP5-8.5'!$C$2:$C$70,"ERROR")) -> 2025-07-20T13:59:56.478Z
A10: 9 | B10: MIROC6 | C10: r1i1p1f1 | D10: All | E10: Annual | F10: Both | G10: 8.1657823 | H10: 1 | I10: 0 | J10: 4 | K10: 7 | L10: 8 | M10: MIROC6.r1i1p1f1 | N10: =IF(ISNA(I10),"--",_xlfn.XLOOKUP($M10,Historical!$A$2:$A$70,Historical!$C$2:$C$70,"ERROR")) -> 2025-07-20T23:02:51.509Z | O10: =IF(ISNA(J10),"--",_xlfn.XLOOKUP($M10,'SSP2-4.5'!$A$2:$A$70,'SSP2-4.5'!$C$2:$C$70,"ERROR")) -> 2025-07-21T04:34:36.773Z | P10: =IF(ISNA(K10),"--",_xlfn.XLOOKUP($M10,'SSP3-7.0'!$A$2:$A$70,'SSP3-7.0'!$C$2:$C$70,"ERROR")) -> 2025-07-21T10:00:41.574Z | Q10: =IF(ISNA(L10),"--",_xlfn.XLOOKUP($M10,'SSP5-8.5'!$A$2:$A$70,'SSP5-8.5'!$C$2:$C$70,"ERROR")) -> 2025-07-21T15:49:37.420Z
A11: 10 | B11: MRI-ESM2-0 | C11: r5i1p1f1 | D11: All | E11: Annual | F11: Both | G11: 9.3994681 | H11: 1 | I11: 0 | J11: =NA() -> #N/A | K11: 7 | L11: =NA() -> #N/A | M11: MRI-ESM2-0.r5i1p1f1 | N11: =IF(ISNA(I11),"--",_xlfn.XLOOKUP($M11,Historical!$A$2:$A$70,Historical!$C$2:$C$70,"ERROR")) -> 2025-07-20T23:01:23.705Z | O11: =IF(ISNA(J11),"--",_xlfn.XLOOKUP($M11,'SSP2-4.5'!$A$2:$A$70,'SSP2-4.5'!$C$2:$C$70,"ERROR")) -> -- | P11: =IF(ISNA(K11),"--",_xlfn.XLOOKUP($M11,'SSP3-7.0'!$A$2:$A$70,'SSP3-7.0'!$C$2:$C$70,"ERROR")) -> 2025-07-21T04:31:06.117Z | Q11: =IF(ISNA(L11),"--",_xlfn.XLOOKUP($M11,'SSP5-8.5'!$A$2:$A$70,'SSP5-8.5'!$C$2:$C$70,"ERROR")) -> --
A12: 11 | B12: INM-CM5-0 | C12: r4i1p1f1 | D12: All | E12: Annual | F12: Both | G12: 9.5958324 | H12: 1 | I12: 0 | J12: =NA() -> #N/A | K12: 7 | L12: =NA() -> #N/A | M12: INM-CM5-0.r4i1p1f1 | N12: =IF(ISNA(I12),"--",_xlfn.XLOOKUP($M12,Historical!$A$2:$A$70,Historical!$C$2:$C$70,"ERROR")) -> 2025-07-21T23:19:40.050Z | O12: =IF(ISNA(J12),"--",_xlfn.XLOOKUP($M12,'SSP2-4.5'!$A$2:$A$70,'SSP2-4.5'!$C$2:$C$70,"ERROR")) -> -- | P12: =IF(ISNA(K12),"--",_xlfn.XLOOKUP($M12,'SSP3-7.0'!$A$2:$A$70,'SSP3-7.0'!$C$2:$C$70,"ERROR")) -> 2025-07-22T04:53:53.035Z | Q12: =IF(ISNA(L12),"--",_xlfn.XLOOKUP($M12,'SSP5-8.5'!$A$2:$A$70,'SSP5-8.5'!$C$2:$C$70,"ERROR")) -> --
A13: 12 | B13: HadGEM3-GC31-MM | C13: r2i1p1f3 | D13: All | E13: Annual | F13: Both | G13: 9.7308787 | H13: 1 | I13: 0 | J13: =NA() -> #N/A | K13: =NA() -> #N/A | L13: 8 | M13: HadGEM3-GC31-MM.r2i1p1f3 | N13: =IF(ISNA(I13),"--",_xlfn.XLOOKUP($M13,Historical!$A$2:$A$70,Historical!$C$2:$C$70,"ERROR")) -> 2025-07-21T23:18:06.214Z | O13: =IF(ISNA(J13),"--",_xlfn.XLOOKUP($M13,'SSP2-4.5'!$A$2:$A$70,'SSP2-4.5'!$C$2:$C$70,"ERROR")) -> -- | P13: =IF(ISNA(K13),"--",_xlfn.XLOOKUP($M13,'SSP3-7.0'!$A$2:$A$70,'SSP3-7.0'!$C$2:$C$70,"ERROR")) -> -- | Q13: =IF(ISNA(L13),"--",_xlfn.XLOOKUP($M13,'SSP5-8.5'!$A$2:$A$70,'SSP5-8.5'!$C$2:$C$70,"ERROR")) -> 2025-07-22T04:59:28.440Z
A14: 13 | B14: NorESM2-LM | C14: r2i1p1f1 | D14: All | E14: Annual | F14: Both | G14: 9.90202 | H14: 1 | I14: 0 | J14: 4 | K14: =NA() -> #N/A | L14: =NA() -> #N/A | M14: NorESM2-LM.r2i1p1f1 | N14: =IF(ISNA(I14),"--",_xlfn.XLOOKUP($M14,Historical!$A$2:$A$70,Historical!$C$2:$C$70,"ERROR")) -> 2025-07-22T22:03:45.693Z | O14: =IF(ISNA(J14),"--",_xlfn.XLOOKUP($M14,'SSP2-4.5'!$A$2:$A$70,'SSP2-4.5'!$C$2:$C$70,"ERROR")) -> 2025-07-23T03:56:03.793Z | P14: =IF(ISNA(K14),"--",_xlfn.XLOOKUP($M14,'SSP3-7.0'!$A$2:$A$70,'SSP3-7.0'!$C$2:$C$70,"ERROR")) -> -- | Q14: =IF(ISNA(L14),"--",_xlfn.XLOOKUP($M14,'SSP5-8.5'!$A$2:$A$70,'SSP5-8.5'!$C$2:$C$70,"ERROR")) -> --
A15: 14 | B15: FGOALS-g3 | C15: r3i1p1f1 | D15: All | E15: Annual | F15: Both | G15: 9.9307603 | H15: 1 | I15: 0 | J15: 4 | K15: 7 | L15: 8 | M15: FGOALS-g3.r3i1p1f1 | N15: =IF(ISNA(I15),"--",_xlfn.XLOOKUP($M15,Historical!$A$2:$A$70,Historical!$C$2:$C$70,"ERROR")) -> 2025-07-22T22:06:36.213Z | O15: =IF(ISNA(J15),"--",_xlfn.XLOOKUP($M15,'SSP2-4.5'!$A$2:$A$70,'SSP2-4.5'!$C$2:$C$70,"ERROR")) -> 2025-07-23T04:00:00.478Z | P15: =IF(ISNA(K15),"--",_xlfn.XLOOKUP($M15,'SSP3-7.0'!$A$2:$A$70,'SSP3-7.0'!$C$2:$C$70,"ERROR")) -> 2025-07-23T09:48:51.958Z | Q15: =IF(ISNA(L15),"--",_xlfn.XLOOKUP($M15,'SSP5-8.5'!$A$2:$A$70,'SSP5-8.5'!$C$2:$C$70,"ERROR")) -> 2025-07-23T15:36:31.387Z
A16: 15 | B16: ACCESS-ESM1-5 | C16: r1i1p1f1 | D16: All | E16: Annual | F16: Both | G16: 10.086129 | H16: 1 | I16: 0 | J16: 4 | K16: 7 | L16: 8 | M16: ACCESS-ESM1-5.r1i1p1f1 | N16: =IF(ISNA(I16),"--",_xlfn.XLOOKUP($M16,Historical!$A$2:$A$70,Historical!$C$2:$C$70,"ERROR")) -> 2025-07-22T22:14:55.100Z | O16: =IF(ISNA(J16),"--",_xlfn.XLOOKUP($M16,'SSP2-4.5'!$A$2:$A$70,'SSP2-4.5'!$C$2:$C$70,"ERROR")) -> 2025-07-23T04:03:17.082Z | P16: =IF(ISNA(K16),"--",_xlfn.XLOOKUP($M16,'SSP3-7.0'!$A$2:$A$70,'SSP3-7.0'!$C$2:$C$70,"ERROR")) -> 2025-07-23T09:52:27.697Z | Q16: =IF(ISNA(L16),"--",_xlfn.XLOOKUP($M16,'SSP5-8.5'!$A$2:$A$70,'SSP5-8.5'!$C$2:$C$70,"ERROR")) -> 2025-07-23T15:36:32.651Z
A17: 16 | B17: HadGEM3-GC31-LL | C17: r3i1p1f3 | D17: All | E17: Annual | F17: Both | G17: 10.124722 | H17: 1 | I17: 0 | J17: =NA() -> #N/A | K17: =NA() -> #N/A | L17: 8 | M17: HadGEM3-GC31-LL.r3i1p1f3 | N17: =IF(ISNA(I17),"--",_xlfn.XLOOKUP($M17,Historical!$A$2:$A$70,Historical!$C$2:$C$70,"ERROR")) -> 2025-07-22T22:16:05.317Z | O17: =IF(ISNA(J17),"--",_xlfn.XLOOKUP($M17,'SSP2-4.5'!$A$2:$A$70,'SSP2-4.5'!$C$2:$C$70,"ERROR")) -> -- | P17: =IF(ISNA(K17),"--",_xlfn.XLOOKUP($M17,'SSP3-7.0'!$A$2:$A$70,'SSP3-7.0'!$C$2:$C$70,"ERROR")) -> -- | Q17: =IF(ISNA(L17),"--",_xlfn.XLOOKUP($M17,'SSP5-8.5'!$A$2:$A$70,'SSP5-8.5'!$C$2:$C$70,"ERROR")) -> 2025-07-23T08:24:47.196Z
A18: 17 | B18: EC-Earth3 | C18: r2i1p1f1 | D18: All | E18: Annual | F18: Both | G18: 10.146428 | H18: 1 | I18: 0 | J18: 4 | K18: =NA() -> #N/A | L18: =NA() -> #N/A | M18: EC-Earth3.r2i1p1f1 | N18: =IF(ISNA(I18),"--",_xlfn.XLOOKUP($M18,Historical!$A$2:$A$70,Historical!$C$2:$C$70,"ERROR")) -> 2025-07-23T02:37:38.094Z | O18: =IF(ISNA(J18),"--",_xlfn.XLOOKUP($M18,'SSP2-4.5'!$A$2:$A$70,'SSP2-4.5'!$C$2:$C$70,"ERROR")) -> 2025-07-23T14:08:33.373Z | P18: =IF(ISNA(K18),"--",_xlfn.XLOOKUP($M18,'SSP3-7.0'!$A$2:$A$70,'SSP3-7.0'!$C$2:$C$70,"ERROR")) -> -- | Q18: =IF(ISNA(L18),"--",_xlfn.XLOOKUP($M18,'SSP5-8.5'!$A$2:$A$70,'SSP5-8.5'!$C$2:$C$70,"ERROR")) -> --
A19: 18 | B19: NorESM2-MM | C19: r2i1p1f1 | D19: All | E19: Annual | F19: Both | G19: 10.246951 | H19: 1 | I19: 0 | J19: 4 | K19: =NA() -> #N/A | L19: =NA() -> #N/A | M19: NorESM2-MM.r2i1p1f1 | N19: =IF(ISNA(I19),"--",_xlfn.XLOOKUP($M19,Historical!$A$2:$A$70,Historical!$C$2:$C$70,"ERROR")) -> 2025-07-23T21:21:59.666Z | O19: =IF(ISNA(J19),"--",_xlfn.XLOOKUP($M19,'SSP2-4.5'!$A$2:$A$70,'SSP2-4.5'!$C$2:$C$70,"ERROR")) -> 2025-07-24T07:30:35.070Z | P19: =IF(ISNA(K19),"--",_xlfn.XLOOKUP($M19,'SSP3-7.0'!$A$2:$A$70,'SSP3-7.0'!$C$2:$C$70,"ERROR")) -> -- | Q19: =IF(ISNA(L19),"--",_xlfn.XLOOKUP($M19,'SSP5-8.5'!$A$2:$A$70,'SSP5-8.5'!$C$2:$C$70,"ERROR")) -> --
A20: 19 | B20: CanESM5 | C20: r1i1p1f1 | D20: All | E20: Annual | F20: Both | G20: 10.595282 | H20: 1 | I20: 0 | J20: 4 | K20: 7 | L20: 8 | M20: CanESM5.r1i1p1f1 | N20: =IF(ISNA(I20),"--",_xlfn.XLOOKUP($M20,Historical!$A$2:$A$70,Historical!$C$2:$C$70,"ERROR")) -> 2025-07-23T21:27:23.092Z | O20: =IF(ISNA(J20),"--",_xlfn.XLOOKUP($M20,'SSP2-4.5'!$A$2:$A$70,'SSP2-4.5'!$C$2:$C$70,"ERROR")) -> 2025-07-24T03:21:50.035Z | P20: =IF(ISNA(K20),"--",_xlfn.XLOOKUP($M20,'SSP3-7.0'!$A$2:$A$70,'SSP3-7.0'!$C$2:$C$70,"ERROR")) -> 2025-07-24T09:15:39.604Z | Q20: =IF(ISNA(L20),"--",_xlfn.XLOOKUP($M20,'SSP5-8.5'!$A$2:$A$70,'SSP5-8.5'!$C$2:$C$70,"ERROR")) -> 2025-07-24T15:05:04.124Z
A21: 20 | B21: ACCESS-CM2 | C21: r1i1p1f1 | D21: All | E21: Annual | F21: Both | G21: 10.657392 | H21: 1 | I21: 0 | J21: 4 | K21: 7 | L21: 8 | M21: ACCESS-CM2.r1i1p1f1 | N21: =IF(ISNA(I21),"--",_xlfn.XLOOKUP($M21,Historical!$A$2:$A$70,Historical!$C$2:$C$70,"ERROR")) -> 2025-07-23T21:19:26.082Z | O21: =IF(ISNA(J21),"--",_xlfn.XLOOKUP($M21,'SSP2-4.5'!$A$2:$A$70,'SSP2-4.5'!$C$2:$C$70,"ERROR")) -> 2025-07-24T03:08:55.616Z | P21: =IF(ISNA(K21),"--",_xlfn.XLOOKUP($M21,'SSP3-7.0'!$A$2:$A$70,'SSP3-7.0'!$C$2:$C$70,"ERROR")) -> 2025-07-24T08:58:57.515Z | Q21: =IF(ISNA(L21),"--",_xlfn.XLOOKUP($M21,'SSP5-8.5'!$A$2:$A$70,'SSP5-8.5'!$C$2:$C$70,"ERROR")) -> 2025-07-24T14:45:43.813Z
A22: 21 | B22: CESM2-LENS | C22: r4i1p1f1 | D22: All | E22: Annual | F22: Both | G22: 10.875201 | H22: 1 | I22: 0 | J22: =NA() -> #N/A | K22: 7 | L22: =NA() -> #N/A | M22: CESM2-LENS.r4i1p1f1 | N22: =IF(ISNA(I22),"--",_xlfn.XLOOKUP($M22,Historical!$A$2:$A$70,Historical!$C$2:$C$70,"ERROR")) -> 2025-07-24T01:47:07.387Z | O22: =IF(ISNA(J22),"--",_xlfn.XLOOKUP($M22,'SSP2-4.5'!$A$2:$A$70,'SSP2-4.5'!$C$2:$C$70,"ERROR")) -> -- | P22: =IF(ISNA(K22),"--",_xlfn.XLOOKUP($M22,'SSP3-7.0'!$A$2:$A$70,'SSP3-7.0'!$C$2:$C$70,"ERROR")) -> 2025-07-24T13:14:17.214Z | Q22: =IF(ISNA(L22),"--",_xlfn.XLOOKUP($M22,'SSP5-8.5'!$A$2:$A$70,'SSP5-8.5'!$C$2:$C$70,"ERROR")) -> --
A23: 22 | B23: IPSL-CM6A-LR | C23: r3i1p1f1 | D23: All | E23: Annual | F23: Both | G23: 10.900917 | H23: 1 | I23: 0 | J23: 4 | K23: 7 | L23: 8 | M23: IPSL-CM6A-LR.r3i1p1f1 | N23: =IF(ISNA(I23),"--",_xlfn.XLOOKUP($M23,Historical!$A$2:$A$70,Historical!$C$2:$C$70,"ERROR")) -> 2025-07-23T21:32:40.430Z | O23: =IF(ISNA(J23),"--",_xlfn.XLOOKUP($M23,'SSP2-4.5'!$A$2:$A$70,'SSP2-4.5'!$C$2:$C$70,"ERROR")) -> 2025-07-24T03:13:31.588Z | P23: =IF(ISNA(K23),"--",_xlfn.XLOOKUP($M23,'SSP3-7.0'!$A$2:$A$70,'SSP3-7.0'!$C$2:$C$70,"ERROR")) -> 2025-07-24T09:19:29.760Z | Q23: =IF(ISNA(L23),"--",_xlfn.XLOOKUP($M23,'SSP5-8.5'!$A$2:$A$70,'SSP5-8.5'!$C$2:$C$70,"ERROR")) -> 2025-07-24T14:55:37.066Z
A24: 23 | B24: EC-Earth3-Veg | C24: r4i1p1f1 | D24: All | E24: Annual | F24: Both | G24: 10.94075 | H24: 1 | I24: 0 | J24: 4 | K24: 7 | L24: 8 | M24: EC-Earth3-Veg.r4i1p1f1 | N24: =IF(ISNA(I24),"--",_xlfn.XLOOKUP($M24,Historical!$A$2:$A$70,Historical!$C$2:$C$70,"ERROR")) -> 2025-07-25T02:23:28.420Z | O24: =IF(ISNA(J24),"--",_xlfn.XLOOKUP($M24,'SSP2-4.5'!$A$2:$A$70,'SSP2-4.5'!$C$2:$C$70,"ERROR")) -> 2025-07-25T08:21:19.704Z | P24: =IF(ISNA(K24),"--",_xlfn.XLOOKUP($M24,'SSP3-7.0'!$A$2:$A$70,'SSP3-7.0'!$C$2:$C$70,"ERROR")) -> 2025-07-25T14:00:42.946Z | Q24: =IF(ISNA(L24),"--",_xlfn.XLOOKUP($M24,'SSP5-8.5'!$A$2:$A$70,'SSP5-8.5'!$C$2:$C$70,"ERROR")) -> 2025-07-25T19:40:42.129Z
A25: 24 | B25: KACE-1-0-G | C25: r2i1p1f1 | D25: All | E25: Annual | F25: Both | G25: 11.248111 | H25: 1 | I25: 0 | J25: 4 | K25: 7 | L25: 8 | M25: KACE-1-0-G.r2i1p1f1 | N25: =IF(ISNA(I25),"--",_xlfn.XLOOKUP($M25,Historical!$A$2:$A$70,Historical!$C$2:$C$70,"ERROR")) -> 2025-07-25T02:25:36.889Z | O25: =IF(ISNA(J25),"--",_xlfn.XLOOKUP($M25,'SSP2-4.5'!$A$2:$A$70,'SSP2-4.5'!$C$2:$C$70,"ERROR")) -> 2025-07-25T08:26:02.075Z | P25: =IF(ISNA(K25),"--",_xlfn.XLOOKUP($M25,'SSP3-7.0'!$A$2:$A$70,'SSP3-7.0'!$C$2:$C$70,"ERROR")) -> 2025-07-25T14:10:14.548Z | Q25: =IF(ISNA(L25),"--",_xlfn.XLOOKUP($M25,'SSP5-8.5'!$A$2:$A$70,'SSP5-8.5'!$C$2:$C$70,"ERROR")) -> 2025-07-25T19:52:26.120Z
A26: 25 | B26: MPI-ESM1-2-HR | C26: r10i1p1f1 | D26: All | E26: Annual | F26: Both | G26: 11.568492 | H26: 1 | I26: 0 | J26: =NA() -> #N/A | K26: 7 | L26: =NA() -> #N/A | M26: MPI-ESM1-2-HR.r10i1p1f1 | N26: =IF(ISNA(I26),"--",_xlfn.XLOOKUP($M26,Historical!$A$2:$A$70,Historical!$C$2:$C$70,"ERROR")) -> 2025-07-25T02:34:45.616Z | O26: =IF(ISNA(J26),"--",_xlfn.XLOOKUP($M26,'SSP2-4.5'!$A$2:$A$70,'SSP2-4.5'!$C$2:$C$70,"ERROR")) -> -- | P26: =IF(ISNA(K26),"--",_xlfn.XLOOKUP($M26,'SSP3-7.0'!$A$2:$A$70,'SSP3-7.0'!$C$2:$C$70,"ERROR")) -> 2025-07-25T08:34:20.027Z | Q26: =IF(ISNA(L26),"--",_xlfn.XLOOKUP($M26,'SSP5-8.5'!$A$2:$A$70,'SSP5-8.5'!$C$2:$C$70,"ERROR")) -> --
A27: 26 | B27: MPI-ESM1-2-LR | C27: r10i1p1f1 | D27: All | E27: Annual | F27: Both | G27: 11.950732 | H27: 1 | I27: 0 | J27: 4 | K27: 7 | L27: 8 | M27: MPI-ESM1-2-LR.r10i1p1f1 | N27: =IF(ISNA(I27),"--",_xlfn.XLOOKUP($M27,Historical!$A$2:$A$70,Historical!$C$2:$C$70,"ERROR")) -> 2025-07-25T02:37:57.316Z | O27: =IF(ISNA(J27),"--",_xlfn.XLOOKUP($M27,'SSP2-4.5'!$A$2:$A$70,'SSP2-4.5'!$C$2:$C$70,"ERROR")) -> 2025-07-25T08:42:27.861Z | P27: =IF(ISNA(K27),"--",_xlfn.XLOOKUP($M27,'SSP3-7.0'!$A$2:$A$70,'SSP3-7.0'!$C$2:$C$70,"ERROR")) -> 2025-07-25T14:26:13.314Z | Q27: =IF(ISNA(L27),"--",_xlfn.XLOOKUP($M27,'SSP5-8.5'!$A$2:$A$70,'SSP5-8.5'!$C$2:$C$70,"ERROR")) -> 2023-07-04T05:38:14.435Z
A28: 27 | B28: AWI-CM-1-1-MR | C28: r1i1p1f1 | D28: All | E28: Annual | F28: Both | G28: 11.980818 | H28: 1 | I28: 0 | J28: 4 | K28: 7 | L28: 8 | M28: AWI-CM-1-1-MR.r1i1p1f1 | N28: =IF(ISNA(I28),"--",_xlfn.XLOOKUP($M28,Historical!$A$2:$A$70,Historical!$C$2:$C$70,"ERROR")) -> 2025-07-26T03:04:58.472Z | O28: =IF(ISNA(J28),"--",_xlfn.XLOOKUP($M28,'SSP2-4.5'!$A$2:$A$70,'SSP2-4.5'!$C$2:$C$70,"ERROR")) -> 2025-07-26T08:54:10.031Z | P28: =IF(ISNA(K28),"--",_xlfn.XLOOKUP($M28,'SSP3-7.0'!$A$2:$A$70,'SSP3-7.0'!$C$2:$C$70,"ERROR")) -> 2025-07-26T14:37:23.877Z | Q28: =IF(ISNA(L28),"--",_xlfn.XLOOKUP($M28,'SSP5-8.5'!$A$2:$A$70,'SSP5-8.5'!$C$2:$C$70,"ERROR")) -> 2025-07-26T20:32:51.486Z
A29: 28 | B29: INM-CM5-0 | C29: r3i1p1f1 | D29: All | E29: Annual | F29: Both | G29: 9.8483501 | H29: 2 | I29: 0 | J29: =NA() -> #N/A | K29: 7 | L29: =NA() -> #N/A | M29: INM-CM5-0.r3i1p1f1 | N29: =IF(ISNA(I29),"--",_xlfn.XLOOKUP($M29,Historical!$A$2:$A$70,Historical!$C$2:$C$70,"ERROR")) -> 2025-07-26T03:09:57.928Z | O29: =IF(ISNA(J29),"--",_xlfn.XLOOKUP($M29,'SSP2-4.5'!$A$2:$A$70,'SSP2-4.5'!$C$2:$C$70,"ERROR")) -> -- | P29: =IF(ISNA(K29),"--",_xlfn.XLOOKUP($M29,'SSP3-7.0'!$A$2:$A$70,'SSP3-7.0'!$C$2:$C$70,"ERROR")) -> 2025-07-26T08:41:31.894Z | Q29: =IF(ISNA(L29),"--",_xlfn.XLOOKUP($M29,'SSP5-8.5'!$A$2:$A$70,'SSP5-8.5'!$C$2:$C$70,"ERROR")) -> --
A30: 29 | B30: FGOALS-g3 | C30: r1i1p1f1 | D30: All | E30: Annual | F30: Both | G30: 9.9428366 | H30: 2 | I30: 0 | J30: 4 | K30: 7 | L30: 8 | M30: FGOALS-g3.r1i1p1f1 | N30: =IF(ISNA(I30),"--",_xlfn.XLOOKUP($M30,Historical!$A$2:$A$70,Historical!$C$2:$C$70,"ERROR")) -> 2025-07-26T03:07:58.121Z | O30: =IF(ISNA(J30),"--",_xlfn.XLOOKUP($M30,'SSP2-4.5'!$A$2:$A$70,'SSP2-4.5'!$C$2:$C$70,"ERROR")) -> 2025-07-26T08:59:56.317Z | P30: =IF(ISNA(K30),"--",_xlfn.XLOOKUP($M30,'SSP3-7.0'!$A$2:$A$70,'SSP3-7.0'!$C$2:$C$70,"ERROR")) -> 2025-07-26T14:44:29.759Z | Q30: =IF(ISNA(L30),"--",_xlfn.XLOOKUP($M30,'SSP5-8.5'!$A$2:$A$70,'SSP5-8.5'!$C$2:$C$70,"ERROR")) -> 2023-07-09T14:28:27.891Z
A31: 30 | B31: MRI-ESM2-0 | C31: r1i1p1f1 | D31: All | E31: Annual | F31: Both | G31: 10.193135 | H31: 2 | I31: 0 | J31: 4 | K31: 7 | L31: 8 | M31: MRI-ESM2-0.r1i1p1f1 | N31: =IF(ISNA(I31),"--",_xlfn.XLOOKUP($M31,Historical!$A$2:$A$70,Historical!$C$2:$C$70,"ERROR")) -> 2025-07-26T03:03:09.134Z | O31: =IF(ISNA(J31),"--",_xlfn.XLOOKUP($M31,'SSP2-4.5'!$A$2:$A$70,'SSP2-4.5'!$C$2:$C$70,"ERROR")) -> 2025-07-26T08:46:04.197Z | P31: =IF(ISNA(K31),"--",_xlfn.XLOOKUP($M31,'SSP3-7.0'!$A$2:$A$70,'SSP3-7.0'!$C$2:$C$70,"ERROR")) -> 2025-07-26T14:24:19.574Z | Q31: =IF(ISNA(L31),"--",_xlfn.XLOOKUP($M31,'SSP5-8.5'!$A$2:$A$70,'SSP5-8.5'!$C$2:$C$70,"ERROR")) -> 2025-07-26T20:14:36.451Z
A32: 31 | B32: NorESM2-LM | C32: r3i1p1f1 | D32: All | E32: Annual | F32: Both | G32: 10.250854 | H32: 2 | I32: 0 | J32: 4 | K32: =NA() -> #N/A | L32: =NA() -> #N/A | M32: NorESM2-LM.r3i1p1f1 | N32: =IF(ISNA(I32),"--",_xlfn.XLOOKUP($M32,Historical!$A$2:$A$70,Historical!$C$2:$C$70,"ERROR")) -> 2023-06-07T01:36:58.307Z | O32: =IF(ISNA(J32),"--",_xlfn.XLOOKUP($M32,'SSP2-4.5'!$A$2:$A$70,'SSP2-4.5'!$C$2:$C$70,"ERROR")) -> 2023-06-07T05:00:58.868Z | P32: =IF(ISNA(K32),"--",_xlfn.XLOOKUP($M32,'SSP3-7.0'!$A$2:$A$70,'SSP3-7.0'!$C$2:$C$70,"ERROR")) -> -- | Q32: =IF(ISNA(L32),"--",_xlfn.XLOOKUP($M32,'SSP5-8.5'!$A$2:$A$70,'SSP5-8.5'!$C$2:$C$70,"ERROR")) -> --
A33: 32 | B33: HadGEM3-GC31-MM | C33: r1i1p1f3 | D33: All | E33: Annual | F33: Both | G33: 10.323759 | H33: 2 | I33: 0 | J33: =NA() -> #N/A | K33: =NA() -> #N/A | L33: 8 | M33: HadGEM3-GC31-MM.r1i1p1f3 | N33: =IF(ISNA(I33),"--",_xlfn.XLOOKUP($M33,Historical!$A$2:$A$70,Historical!$C$2:$C$70,"ERROR")) -> 2023-06-08T09:31:42.562Z | O33: =IF(ISNA(J33),"--",_xlfn.XLOOKUP($M33,'SSP2-4.5'!$A$2:$A$70,'SSP2-4.5'!$C$2:$C$70,"ERROR")) -> -- | P33: =IF(ISNA(K33),"--",_xlfn.XLOOKUP($M33,'SSP3-7.0'!$A$2:$A$70,'SSP3-7.0'!$C$2:$C$70,"ERROR")) -> -- | Q33: =IF(ISNA(L33),"--",_xlfn.XLOOKUP($M33,'SSP5-8.5'!$A$2:$A$70,'SSP5-8.5'!$C$2:$C$70,"ERROR")) -> 2023-06-08T14:42:41.111Z
A34: 33 | B34: MIROC6 | C34: r2i1p1f1 | D34: All | E34: Annual | F34: Both | G34: 10.395672 | H34: 2 | I34: 0 | J34: 4 | K34: 7 | L34: 8 | M34: MIROC6.r2i1p1f1 | N34: =IF(ISNA(I34),"--",_xlfn.XLOOKUP($M34,Historical!$A$2:$A$70,Historical!$C$2:$C$70,"ERROR")) -> 2023-06-08T18:26:33.679Z | O34: =IF(ISNA(J34),"--",_xlfn.XLOOKUP($M34,'SSP2-4.5'!$A$2:$A$70,'SSP2-4.5'!$C$2:$C$70,"ERROR")) -> 2023-06-08T23:39:17.619Z | P34: =IF(ISNA(K34),"--",_xlfn.XLOOKUP($M34,'SSP3-7.0'!$A$2:$A$70,'SSP3-7.0'!$C$2:$C$70,"ERROR")) -> 2023-06-08T23:45:27.071Z | Q34: =IF(ISNA(L34),"--",_xlfn.XLOOKUP($M34,'SSP5-8.5'!$A$2:$A$70,'SSP5-8.5'!$C$2:$C$70,"ERROR")) -> 2023-06-08T23:53:25.196Z
A35: 34 | B35: ACCESS-ESM1-5 | C35: r5i1p1f1 | D35: All | E35: Annual | F35: Both | G35: 10.676142 | H35: 2 | I35: 0 | J35: 4 | K35: 7 | L35: 8 | M35: ACCESS-ESM1-5.r5i1p1f1 | N35: =IF(ISNA(I35),"--",_xlfn.XLOOKUP($M35,Historical!$A$2:$A$70,Historical!$C$2:$C$70,"ERROR")) -> 2023-06-08T18:41:48.449Z | O35: =IF(ISNA(J35),"--",_xlfn.XLOOKUP($M35,'SSP2-4.5'!$A$2:$A$70,'SSP2-4.5'!$C$2:$C$70,"ERROR")) -> 2023-06-08T23:49:50.942Z | P35: =IF(ISNA(K35),"--",_xlfn.XLOOKUP($M35,'SSP3-7.0'!$A$2:$A$70,'SSP3-7.0'!$C$2:$C$70,"ERROR")) -> 2023-06-08T23:53:39.172Z | Q35: =IF(ISNA(L35),"--",_xlfn.XLOOKUP($M35,'SSP5-8.5'!$A$2:$A$70,'SSP5-8.5'!$C$2:$C$70,"ERROR")) -> 2023-06-08T23:44:02.130Z
A36: 35 | B36: ACCESS-CM2 | C36: r3i1p1f1 | D36: All | E36: Annual | F36: Both | G36: 10.747093 | H36: 2 | I36: 0 | J36: 4 | K36: 7 | L36: 8 | M36: ACCESS-CM2.r3i1p1f1 | N36: =IF(ISNA(I36),"--",_xlfn.XLOOKUP($M36,Historical!$A$2:$A$70,Historical!$C$2:$C$70,"ERROR")) -> 2023-06-09T04:10:18.992Z | O36: =IF(ISNA(J36),"--",_xlfn.XLOOKUP($M36,'SSP2-4.5'!$A$2:$A$70,'SSP2-4.5'!$C$2:$C$70,"ERROR")) -> 2023-06-09T06:55:33.364Z | P36: =IF(ISNA(K36),"--",_xlfn.XLOOKUP($M36,'SSP3-7.0'!$A$2:$A$70,'SSP3-7.0'!$C$2:$C$70,"ERROR")) -> 2023-06-09T06:52:31.430Z | Q36: =IF(ISNA(L36),"--",_xlfn.XLOOKUP($M36,'SSP5-8.5'!$A$2:$A$70,'SSP5-8.5'!$C$2:$C$70,"ERROR")) -> 2023-06-09T06:52:42.210Z
A37: 36 | B37: EC-Earth3 | C37: r4i1p1f1 | D37: All | E37: Annual | F37: Both | G37: 10.884393 | H37: 2 | I37: 0 | J37: 4 | K37: 7 | L37: 8 | M37: EC-Earth3.r4i1p1f1 | N37: =IF(ISNA(I37),"--",_xlfn.XLOOKUP($M37,Historical!$A$2:$A$70,Historical!$C$2:$C$70,"ERROR")) -> 2023-06-10T16:54:37.450Z | O37: =IF(ISNA(J37),"--",_xlfn.XLOOKUP($M37,'SSP2-4.5'!$A$2:$A$70,'SSP2-4.5'!$C$2:$C$70,"ERROR")) -> 2023-06-10T20:48:39.159Z | P37: =IF(ISNA(K37),"--",_xlfn.XLOOKUP($M37,'SSP3-7.0'!$A$2:$A$70,'SSP3-7.0'!$C$2:$C$70,"ERROR")) -> 2023-06-10T20:54:11.962Z | Q37: =IF(ISNA(L37),"--",_xlfn.XLOOKUP($M37,'SSP5-8.5'!$A$2:$A$70,'SSP5-8.5'!$C$2:$C$70,"ERROR")) -> 2023-06-10T20:51:19.076Z
A38: 37 | B38: CESM2-LENS | C38: r6i1p1f1 | D38: All | E38: Annual | F38: Both | G38: 10.90642 | H38: 2 | I38: 0 | J38: =NA() -> #N/A | K38: 7 | L38: =NA() -> #N/A | M38: CESM2-LENS.r6i1p1f1 | N38: =IF(ISNA(I38),"--",_xlfn.XLOOKUP($M38,Historical!$A$2:$A$70,Historical!$C$2:$C$70,"ERROR")) -> 2023-06-10T16:55:46.223Z | O38: =IF(ISNA(J38),"--",_xlfn.XLOOKUP($M38,'SSP2-4.5'!$A$2:$A$70,'SSP2-4.5'!$C$2:$C$70,"ERROR")) -> -- | P38: =IF(ISNA(K38),"--",_xlfn.XLOOKUP($M38,'SSP3-7.0'!$A$2:$A$70,'SSP3-7.0'!$C$2:$C$70,"ERROR")) -> 2023-06-11T12:37:37.883Z | Q38: =IF(ISNA(L38),"--",_xlfn.XLOOKUP($M38,'SSP5-8.5'!$A$2:$A$70,'SSP5-8.5'!$C$2:$C$70,"ERROR")) -> --
A39: 38 | B39: NorESM2-MM | C39: r1i1p1f1 | D39: All | E39: Annual | F39: Both | G39: 11.102702 | H39: 2 | I39: 0 | J39: 4 | K39: 7 | L39: 8 | M39: NorESM2-MM.r1i1p1f1 | N39: =IF(ISNA(I39),"--",_xlfn.XLOOKUP($M39,Historical!$A$2:$A$70,Historical!$C$2:$C$70,"ERROR")) -> 2023-08-29T03:34:35.654Z | O39: =IF(ISNA(J39),"--",_xlfn.XLOOKUP($M39,'SSP2-4.5'!$A$2:$A$70,'SSP2-4.5'!$C$2:$C$70,"ERROR")) -> 2023-07-05T02:28:48.958Z | P39: =IF(ISNA(K39),"--",_xlfn.XLOOKUP($M39,'SSP3-7.0'!$A$2:$A$70,'SSP3-7.0'!$C$2:$C$70,"ERROR")) -> 2023-07-05T02:30:43.591Z | Q39: =IF(ISNA(L39),"--",_xlfn.XLOOKUP($M39,'SSP5-8.5'!$A$2:$A$70,'SSP5-8.5'!$C$2:$C$70,"ERROR")) -> 2023-06-10T20:54:13.370Z
A40: 39 | B40: EC-Earth3-Veg | C40: r3i1p1f1 | D40: All | E40: Annual | F40: Both | G40: 11.244554 | H40: 2 | I40: 0 | J40: 4 | K40: 7 | L40: 8 | M40: EC-Earth3-Veg.r3i1p1f1 | N40: =IF(ISNA(I40),"--",_xlfn.XLOOKUP($M40,Historical!$A$2:$A$70,Historical!$C$2:$C$70,"ERROR")) -> 2023-06-10T16:54:42.394Z | O40: =IF(ISNA(J40),"--",_xlfn.XLOOKUP($M40,'SSP2-4.5'!$A$2:$A$70,'SSP2-4.5'!$C$2:$C$70,"ERROR")) -> 2023-07-02T08:05:19.461Z | P40: =IF(ISNA(K40),"--",_xlfn.XLOOKUP($M40,'SSP3-7.0'!$A$2:$A$70,'SSP3-7.0'!$C$2:$C$70,"ERROR")) -> 2023-07-02T08:08:50.527Z | Q40: =IF(ISNA(L40),"--",_xlfn.XLOOKUP($M40,'SSP5-8.5'!$A$2:$A$70,'SSP5-8.5'!$C$2:$C$70,"ERROR")) -> 2023-07-02T08:05:07.009Z
...
